Workbook

Sheet zadání
A1: Předmět: | C1: Vzor
A3: Finanční limit: | C3: 0 | D3: Kč
A5: Plnění: | C5: ='součty'!D87 -> 509.41 | D5: Kč
A7: Rozdíl: | C7: =C3-C5 -> -509.41 | D7: Kč
C18: Neplátce DPH | D18: FALSE

Sheet Výpočet dřeva
A1: Název dílu | B1: Typ dřeva | C1: Šířka | D1: Výška | E1: Tloušťka | F1: Povrchovka | G1: Počet | H1: Plocha m2 | I1: TL fošny | J1: Objem m3 | K1: Cena/m3 | L1: Cena
B2: Nic | H2: =(C2*0.001*D2*0.001)*G2 -> 0 | I2: =IF(E2 < 29,32,50) -> 32 | J2: =H2*I2*0.001 -> 0 | K2: =VLOOKUP(B2,'Ceník dřeva'!$A$2:$D$18,IF(I2 < 50,2,4),0) -> 0 | L2: =J2*K2 -> 0
B3: Nic | H3: =(C3*0.001*D3*0.001)*G3 -> 0 | I3: =IF(E3 < 29,32,50) -> 32 | J3: =H3*I3*0.001 -> 0 | K3: =VLOOKUP(B3,'Ceník dřeva'!$A$2:$D$18,IF(I3 < 50,2,4),0) -> 0 | L3: =J3*K3 -> 0
B4: Nic | H4: =(C4*0.001*D4*0.001)*G4 -> 0 | I4: =IF(E4 < 29,32,50) -> 32 | J4: =H4*I4*0.001 -> 0 | K4: =VLOOKUP(B4,'Ceník dřeva'!$A$2:$D$18,IF(I4 < 50,2,4),0) -> 0 | L4: =J4*K4 -> 0
B5: Nic | H5: =(C5*0.001*D5*0.001)*G5 -> 0 | I5: =IF(E5 < 29,32,50) -> 32 | J5: =H5*I5*0.001 -> 0 | K5: =VLOOKUP(B5,'Ceník dřeva'!$A$2:$D$18,IF(I5 < 50,2,4),0) -> 0 | L5: =J5*K5 -> 0
B6: Nic | H6: =(C6*0.001*D6*0.001)*G6 -> 0 | I6: =IF(E6 < 29,32,50) -> 32 | J6: =H6*I6*0.001 -> 0 | K6: =VLOOKUP(B6,'Ceník dřeva'!$A$2:$D$18,IF(I6 < 50,2,4),0) -> 0 | L6: =J6*K6 -> 0
B7: Nic | H7: =(C7*0.001*D7*0.001)*G7 -> 0 | I7: =IF(E7 < 29,32,50) -> 32 | J7: =H7*I7*0.001 -> 0 | K7: =VLOOKUP(B7,'Ceník dřeva'!$A$2:$D$18,IF(I7 < 50,2,4),0) -> 0 | L7: =J7*K7 -> 0
B8: Nic | H8: =(C8*0.001*D8*0.001)*G8 -> 0 | I8: =IF(E8 < 29,32,50) -> 32 | J8: =H8*I8*0.001 -> 0 | K8: =VLOOKUP(B8,'Ceník dřeva'!$A$2:$D$18,IF(I8 < 50,2,4),0) -> 0 | L8: =J8*K8 -> 0
B9: Nic | H9: =(C9*0.001*D9*0.001)*G9 -> 0 | I9: =IF(E9 < 29,32,50) -> 32 | J9: =H9*I9*0.001 -> 0 | K9: =VLOOKUP(B9,'Ceník dřeva'!$A$2:$D$18,IF(I9 < 50,2,4),0) -> 0 | L9: =J9*K9 -> 0
B10: Nic | H10: =(C10*0.001*D10*0.001)*G10 -> 0 | I10: =IF(E10 < 29,32,50) -> 32 | J10: =H10*I10*0.001 -> 0 | K10: =VLOOKUP(B10,'Ceník dřeva'!$A$2:$D$18,IF(I10 < 50,2,4),0) -> 0 | L10: =J10*K10 -> 0
B11: Nic | H11: =(C11*0.001*D11*0.001)*G11 -> 0 | I11: =IF(E11 < 29,32,50) -> 32 | J11: =H11*I11*0.001 -> 0 | K11: =VLOOKUP(B11,'Ceník dřeva'!$A$2:$D$18,IF(I11 < 50,2,4),0) -> 0 | L11: =J11*K11 -> 0
B12: Nic | H12: =(C12*0.001*D12*0.001)*G12 -> 0 | I12: =IF(E12 < 29,32,50) -> 32 | J12: =H12*I12*0.001 -> 0 | K12: =VLOOKUP(B12,'Ceník dřeva'!$A$2:$D$18,IF(I12 < 50,2,4),0) -> 0 | L12: =J12*K12 -> 0
B13: Nic | H13: =(C13*0.001*D13*0.001)*G13 -> 0 | I13: =IF(E13 < 29,32,50) -> 32 | J13: =H13*I13*0.001 -> 0 | K13: =VLOOKUP(B13,'Ceník dřeva'!$A$2:$D$18,IF(I13 < 50,2,4),0) -> 0 | L13: =J13*K13 -> 0
... B50: Nic | H50: =(C50*0.001*D50*0.001)*G50 -> 0 | I50: =IF(E50 < 29,32,50) -> 32 | J50: =H50*I50*0.001 -> 0 | K50: =VLOOKUP(B50,'Ceník dřeva'!$A$2:$D$18,IF(I50 < 50,2,4),0) -> 0 | L50: =J50*K50 -> 0
N52: Objem celkem | O52: =SUBTOTAL(9,J2:J50) -> 0
N53: Objem s rezervou | O53: =O52*1.25 -> 0
N55: Cena celkem | O55: =SUBTOTAL(9,L2:L50) -> 0
N56: Cena s rezervou | O56: =O55*1.25 -> 0
N57: Cena s rezervou + DPH | O57: =O56*1.21 -> 0

Sheet Nákup

Sheet Ceník dřeva
A1: Druh řeziva | B1: 32 | C1: 40 | D1: 50 | E1: 60 | F1: 30 kratina
A2: Dub | B2: 21900 | D2: 29900
A3: Buk | B3: 11000 | D3: 12300
A4: Jasan | B4: 13000 | D4: 14500
A5: Javor | B5: 13000 | D5: 14000
A6: Smrk | B6: 11500 | D6: 12300
A7: Jedle | D7: 12100
A8: Borovice | B8: 11000 | D8: 11500
A9: Modřín | B9: 11500 | D9: 12500
A10: Olše | B10: 10500 | D10: 11500
A11: Ořešák | B11: 24000 | D11: 30500
A12: Bříza | B12: 8500 | D12: 8900
A13: Topol | B13: 8000 | D13: 8400
A14: Lípa | B14: 10000 | D14: 10500
A15: Akát
A16: Třešeň | B16: 15000 | D16: 16000
A17: Jilm
A18: Nic | B18: 0 | D18: 0

Sheet Ceník mechanizace
A2: Fakturace bez DPH
A3: Doprava | B3: Položka: | C3: Popis: | D3: Kč/Km
B4: Osobák | D4: 9
B5: Dodávka | D5: 17
B6: Malý vozík | C6: 200 | D6: 3
A7: Mechanizace | B7: Položka: | C7: Popis: | D7: Kč/hod
B8: Pokosová pila | D8: 30
B9: Formátovací pila | D9: 260 | G9: 250000 | H9: 1000 | I9: 10
B10: Hoblovka | D10: 140 | G10: 100000 | H10: 1000 | J10: 6000 | K10: 200 | L10: =J10/K10 -> 30
B11: Frézka | D11: 250
B12: Fréza palubky - m | C12: měkké dřevo | D12: 200
B13: Fréza palubky - t | C13: tvrdé dřevo | D13: 500
B14: Fréza zaoblovací | D14: 100
B15: Ruční frézka | D15: 30
D16: 0
D17: 0
D18: 0
D19: 0
D20: 0
D21: 0
D22: 0
D23: 0
D24: 0
D25: 0
D26: 0
D27: 0
D28: 0
B29: Vysavač | D29: 10
B30: Odsávání | D30: 20
B31: Excentrická bruska | D31: 20

Sheet Ceník - ostatní materiál
A1: Fakturace bez DPH
A2: Spojovací materiál | B2: Položka: | C2: Popis: | D2: Kč/ks
B3: Lepidlo | D3: 50
B4: Kolík 8x40 | D4: 0.35
B5: Šroub M6 | D5: 1.5
B6: Insert M6 | D6: 0.5
B7: Panty
A41: Povrchovka | B41: Položka: | C41: Popis: | D41: Kč/m2
B42: Osmo | D42: =2687/(24*3) -> 37.319444
A54: Brusný materiál | B54: Položka: | C54: Popis: | D54: Kč/ks
B55: Brusný výsek 150 mm | D55: 15
B56: Brusný výsek houbička | D56: 8
B57: Brusný pás | D57: 70
B58: Houba na povrchovku | D58: 20

Sheet práce
A1: Práce
A3: Martin | B3: MJ | C3: počet MJ | D3: Kč/MJ | E3: Kč celkem | G3: Vlaďka | H3: MJ | I3: počet MJ | J3: Kč/MJ | K3: Kč celkem | N3: MJ | O3: počet MJ | P3: Kč/MJ | Q3: Kč celkem | T3: MJ | U3: počet MJ | V3: Kč/MJ | W3: Kč celkem | Z3: MJ | AA3: počet MJ | AB3: Kč/MJ | AC3: Kč celkem | AF3: MJ | AG3: počet MJ | AH3: Kč/MJ | AI3: Kč celkem | AL3: MJ | AM3: počet MJ | AN3: Kč/MJ | AO3: Kč celkem | AR3: MJ | AS3: počet MJ | AT3: Kč/MJ | AU3: Kč celkem | AX3: MJ | AY3: počet MJ | AZ3: Kč/MJ | BA3: Kč celkem | BD3: MJ | BE3: počet MJ | BF3: Kč/MJ | BG3: Kč celkem | BJ3: MJ | BK3: počet MJ | BL3: Kč/MJ | BM3: Kč celkem | BP3: MJ | BQ3: počet MJ | BR3: Kč/MJ | BS3: Kč celkem | BV3: MJ | BW3: počet MJ | BX3: Kč/MJ | BY3: Kč celkem | CB3: MJ | CC3: počet MJ | CD3: Kč/MJ | CE3: Kč celkem | CH3: hod | CI3: Kč
A4: 0 | B4: hod | D4: 500 | E4: =C4*D4 -> 0 | G4: =A4 -> 0 | H4: =B4 -> hod | J4: 400 | K4: =I4*J4 -> 0 | M4: =A4 -> 0 | N4: =H4 -> hod | P4: 700 | Q4: =O4*P4 -> 0 | S4: =A4 -> 0 | T4: =N4 -> hod | V4: 650 | W4: =U4*V4 -> 0 | Y4: =A4 -> 0 | Z4: =T4 -> hod | AB4: 650 | AC4: =AA4*AB4 -> 0 | AE4: =A4 -> 0 | AF4: =Z4 -> hod | AH4: 700 | AI4: =AG4*AH4 -> 0 | AK4: =G4 -> 0 | AL4: =AF4 -> hod | AN4: 600 | AO4: =AM4*AN4 -> 0 | AQ4: =AK4 -> 0 | AR4: =AL4 -> hod | AT4: 600 | AU4: =AS4*AT4 -> 0 | AW4: =A4 -> 0 | AX4: =AF4 -> hod | AZ4: 600 | BA4: =AY4*AZ4 -> 0 | BC4: =A4 -> 0 | BD4: =AX4 -> hod | BF4: 600 | BG4: =BE4*BF4 -> 0 | BI4: =G4 -> 0 | BJ4: =BD4 -> hod | BL4: 800 | BM4: =BK4*BL4 -> 0 | BO4: =M4 -> 0 | BP4: =BJ4 -> hod | BR4: 650 | BS4: =BQ4*BR4 -> 0 | BU4: =S4 -> 0 | BV4: =BP4 -> hod | BX4: 950 | BY4: =BW4*BX4 -> 0 | CA4: =Y4 -> 0 | CB4: =BV4 -> hod | CD4: 600 | CE4: =CC4*CD4 -> 0 | CG4: =A4 -> 0 | CH4: =C4+I4+O4+U4+AA4+AG4+AM4+AS4+AY4+BE4+BK4+BQ4+BW4+CC4 -> 0 | CI4: =E4+K4+Q4+W4+AC4+AI4+AO4+AU4+BA4+BG4+BM4+BS4+BY4+CE4 -> 0
A5: 0 | B5: hod | D5: =D4 -> 500 | E5: =C5*D5 -> 0 | G5: =A5 -> 0 | H5: =B5 -> hod | J5: =J4 -> 400 | K5: =I5*J5 -> 0 | M5: =A5 -> 0 | N5: =H5 -> hod | P5: =P4 -> 700 | Q5: =O5*P5 -> 0 | S5: =A5 -> 0 | T5: =N5 -> hod | V5: =V4 -> 650 | W5: =U5*V5 -> 0 | Y5: =A5 -> 0 | Z5: =T5 -> hod | AB5: =AB4 -> 650 | AC5: =AA5*AB5 -> 0 | AE5: =A5 -> 0 | AF5: =Z5 -> hod | AH5: =AH4 -> 700 | AI5: =AG5*AH5 -> 0 | AK5: =G5 -> 0 | AL5: =AF5 -> hod | AN5: =AN4 -> 600 | AO5: =AM5*AN5 -> 0 | AQ5: =AK5 -> 0 | AR5: =AL5 -> hod | AT5: =AT4 -> 600 | AU5: =AS5*AT5 -> 0 | AW5: =A5 -> 0 | AX5: =AF5 -> hod | AZ5: =AZ4 -> 600 | BA5: =AY5*AZ5 -> 0 | BC5: =A5 -> 0 | BD5: =AX5 -> hod | BF5: =BF4 -> 600 | BG5: =BE5*BF5 -> 0 | BI5: =G5 -> 0 | BJ5: =BD5 -> hod | BL5: =BL4 -> 800 | BM5: =BK5*BL5 -> 0 | BO5: =M5 -> 0 | BP5: =BJ5 -> hod | BR5: =BR4 -> 650 | BS5: =BQ5*BR5 -> 0 | BU5: =S5 -> 0 | BV5: =BP5 -> hod | BX5: =BX4 -> 950 | BY5: =BW5*BX5 -> 0 | CA5: =Y5 -> 0 | CB5: =BV5 -> hod | CD5: =CD4 -> 600 | CE5: =CC5*CD5 -> 0 | CG5: =A5 -> 0 | CH5: =C5+I5+O5+U5+AA5+AG5+AM5+AS5+AY5+BE5+BK5 -> 0 | CI5: =E5+K5+Q5+W5+AC5+AI5+AO5+AU5+BA5+BG5+BM5 -> 0
A6: 0 | B6: hod | D6: =D5 -> 500 | E6: =C6*D6 -> 0 | G6: =A6 -> 0 | H6: =B6 -> hod | J6: =J5 -> 400 | K6: =I6*J6 -> 0 | M6: =A6 -> 0 | N6: =H6 -> hod | P6: =P5 -> 700 | Q6: =O6*P6 -> 0 | S6: =A6 -> 0 | T6: =N6 -> hod | V6: =V5 -> 650 | W6: =U6*V6 -> 0 | Y6: =A6 -> 0 | Z6: =T6 -> hod | AB6: =AB5 -> 650 | AC6: =AA6*AB6 -> 0 | AE6: =A6 -> 0 | AF6: =Z6 -> hod | AH6: =AH5 -> 700 | AI6: =AG6*AH6 -> 0 | AK6: =G6 -> 0 | AL6: =AF6 -> hod | AN6: =AN5 -> 600 | AO6: =AM6*AN6 -> 0 | AQ6: =AK6 -> 0 | AR6: =AL6 -> hod | AT6: =AT5 -> 600 | AU6: =AS6*AT6 -> 0 | AW6: =A6 -> 0 | AX6: =AF6 -> hod | AZ6: =AZ5 -> 600 | BA6: =AY6*AZ6 -> 0 | BC6: =A6 -> 0 | BD6: =AX6 -> hod | BF6: =BF5 -> 600 | BG6: =BE6*BF6 -> 0 | BI6: =G6 -> 0 | BJ6: =BD6 -> hod | BL6: =BL5 -> 800 | BM6: =BK6*BL6 -> 0 | BO6: =M6 -> 0 | BP6: =BJ6 -> hod | BR6: =BR5 -> 650 | BS6: =BQ6*BR6 -> 0 | BU6: =S6 -> 0 | BV6: =BP6 -> hod | BX6: =BX5 -> 950 | BY6: =BW6*BX6 -> 0 | CA6: =Y6 -> 0 | CB6: =BV6 -> hod | CD6: =CD5 -> 600 | CE6: =CC6*CD6 -> 0 | CG6: =A6 -> 0 | CH6: =C6+I6+O6+U6+AA6+AG6+AM6+AS6+AY6+BE6+BK6 -> 0 | CI6: =E6+K6+Q6+W6+AC6+AI6+AO6+AU6+BA6+BG6+BM6 -> 0
A7: 0 | B7: hod | D7: =D6 -> 500 | E7: =C7*D7 -> 0 | G7: =A7 -> 0 | H7: =B7 -> hod | J7: =J6 -> 400 | K7: =I7*J7 -> 0 | M7: =A7 -> 0 | N7: =H7 -> hod | P7: =P6 -> 700 | Q7: =O7*P7 -> 0 | S7: =A7 -> 0 | T7: =N7 -> hod | V7: =V6 -> 650 | W7: =U7*V7 -> 0 | Y7: =A7 -> 0 | Z7: =T7 -> hod | AB7: =AB6 -> 650 | AC7: =AA7*AB7 -> 0 | AE7: =A7 -> 0 | AF7: =Z7 -> hod | AH7: =AH6 -> 700 | AI7: =AG7*AH7 -> 0 | AK7: =G7 -> 0 | AL7: =AF7 -> hod | AN7: =AN6 -> 600 | AO7: =AM7*AN7 -> 0 | AQ7: =AK7 -> 0 | AR7: =AL7 -> hod | AT7: =AT6 -> 600 | AU7: =AS7*AT7 -> 0 | AW7: =A7 -> 0 | AX7: =AF7 -> hod | AZ7: =AZ6 -> 600 | BA7: =AY7*AZ7 -> 0 | BC7: =A7 -> 0 | BD7: =AX7 -> hod | BF7: =BF6 -> 600 | BG7: =BE7*BF7 -> 0 | BI7: =G7 -> 0 | BJ7: =BD7 -> hod | BL7: =BL6 -> 800 | BM7: =BK7*BL7 -> 0 | BO7: =M7 -> 0 | BP7: =BJ7 -> hod | BR7: =BR6 -> 650 | BS7: =BQ7*BR7 -> 0 | BU7: =S7 -> 0 | BV7: =BP7 -> hod | BX7: =BX6 -> 950 | BY7: =BW7*BX7 -> 0 | CA7: =Y7 -> 0 | CB7: =BV7 -> hod | CD7: =CD6 -> 600 | CE7: =CC7*CD7 -> 0 | CG7: =A7 -> 0 | CH7: =C7+I7+O7+U7+AA7+AG7+AM7+AS7+AY7+BE7+BK7 -> 0 | CI7: =E7+K7+Q7+W7+AC7+AI7+AO7+AU7+BA7+BG7+BM7 -> 0
A8: 0 | B8: hod | D8: =D7 -> 500 | E8: =C8*D8 -> 0 | G8: =A8 -> 0 | H8: =B8 -> hod | J8: =J7 -> 400 | K8: =I8*J8 -> 0 | M8: =A8 -> 0 | N8: =H8 -> hod | P8: =P7 -> 700 | Q8: =O8*P8 -> 0 | S8: =A8 -> 0 | T8: =N8 -> hod | V8: =V7 -> 650 | W8: =U8*V8 -> 0 | Y8: =A8 -> 0 | Z8: =T8 -> hod | AB8: =AB7 -> 650 | AC8: =AA8*AB8 -> 0 | AE8: =A8 -> 0 | AF8: =Z8 -> hod | AH8: =AH7 -> 700 | AI8: =AG8*AH8 -> 0 | AK8: =G8 -> 0 | AL8: =AF8 -> hod | AN8: =AN7 -> 600 | AO8: =AM8*AN8 -> 0 | AQ8: =AK8 -> 0 | AR8: =AL8 -> hod | AT8: =AT7 -> 600 | AU8: =AS8*AT8 -> 0 | AW8: =A8 -> 0 | AX8: =AF8 -> hod | AZ8: =AZ7 -> 600 | BA8: =AY8*AZ8 -> 0 | BC8: =A8 -> 0 | BD8: =AX8 -> hod | BF8: =BF7 -> 600 | BG8: =BE8*BF8 -> 0 | BI8: =G8 -> 0 | BJ8: =BD8 -> hod | BL8: =BL7 -> 800 | BM8: =BK8*BL8 -> 0 | BO8: =M8 -> 0 | BP8: =BJ8 -> hod | BR8: =BR7 -> 650 | BS8: =BQ8*BR8 -> 0 | BU8: =S8 -> 0 | BV8: =BP8 -> hod | BX8: =BX7 -> 950 | BY8: =BW8*BX8 -> 0 | CA8: =Y8 -> 0 | CB8: =BV8 -> hod | CD8: =CD7 -> 600 | CE8: =CC8*CD8 -> 0 | CG8: =A8 -> 0 | CH8: =C8+I8+O8+U8+AA8+AG8+AM8+AS8+AY8+BE8+BK8 -> 0 | CI8: =E8+K8+Q8+W8+AC8+AI8+AO8+AU8+BA8+BG8+BM8 -> 0
A9: 0 | B9: hod | D9: =D8 -> 500 | E9: =C9*D9 -> 0 | G9: =A9 -> 0 | H9: =B9 -> hod | J9: =J8 -> 400 | K9: =I9*J9 -> 0 | M9: =A9 -> 0 | N9: =H9 -> hod | P9: =P8 -> 700 | Q9: =O9*P9 -> 0 | S9: =A9 -> 0 | T9: =N9 -> hod | V9: =V8 -> 650 | W9: =U9*V9 -> 0 | Y9: =A9 -> 0 | Z9: =T9 -> hod | AB9: =AB8 -> 650 | AC9: =AA9*AB9 -> 0 | AE9: =A9 -> 0 | AF9: =Z9 -> hod | AH9: =AH8 -> 700 | AI9: =AG9*AH9 -> 0 | AK9: =G9 -> 0 | AL9: =AF9 -> hod | AN9: =AN8 -> 600 | AO9: =AM9*AN9 -> 0 | AQ9: =AK9 -> 0 | AR9: =AL9 -> hod | AT9: =AT8 -> 600 | AU9: =AS9*AT9 -> 0 | AW9: =A9 -> 0 | AX9: =AF9 -> hod | AZ9: =AZ8 -> 600 | BA9: =AY9*AZ9 -> 0 | BC9: =A9 -> 0 | BD9: =AX9 -> hod | BF9: =BF8 -> 600 | BG9: =BE9*BF9 -> 0 | BI9: =G9 -> 0 | BJ9: =BD9 -> hod | BL9: =BL8 -> 800 | BM9: =BK9*BL9 -> 0 | BO9: =M9 -> 0 | BP9: =BJ9 -> hod | BR9: =BR8 -> 650 | BS9: =BQ9*BR9 -> 0 | BU9: =S9 -> 0 | BV9: =BP9 -> hod | BX9: =BX8 -> 950 | BY9: =BW9*BX9 -> 0 | CA9: =Y9 -> 0 | CB9: =BV9 -> hod | CD9: =CD8 -> 600 | CE9: =CC9*CD9 -> 0 | CG9: =A9 -> 0 | CH9: =C9+I9+O9+U9+AA9+AG9+AM9+AS9+AY9+BE9+BK9 -> 0 | CI9: =E9+K9+Q9+W9+AC9+AI9+AO9+AU9+BA9+BG9+BM9 -> 0
A10: 0 | B10: hod | D10: =D9 -> 500 | E10: =C10*D10 -> 0 | G10: =A10 -> 0 | H10: =B10 -> hod | J10: =J9 -> 400 | K10: =I10*J10 -> 0 | M10: =A10 -> 0 | N10: =H10 -> hod | P10: =P9 -> 700 | Q10: =O10*P10 -> 0 | S10: =A10 -> 0 | T10: =N10 -> hod | V10: =V9 -> 650 | W10: =U10*V10 -> 0 | Y10: =A10 -> 0 | Z10: =T10 -> hod | AB10: =AB9 -> 650 | AC10: =AA10*AB10 -> 0 | AE10: =A10 -> 0 | AF10: =Z10 -> hod | AH10: =AH9 -> 700 | AI10: =AG10*AH10 -> 0 | AK10: =G10 -> 0 | AL10: =AF10 -> hod | AN10: =AN9 -> 600 | AO10: =AM10*AN10 -> 0 | AQ10: =AK10 -> 0 | AR10: =AL10 -> hod | AT10: =AT9 -> 600 | AU10: =AS10*AT10 -> 0 | AW10: =A10 -> 0 | AX10: =AF10 -> hod | AZ10: =AZ9 -> 600 | BA10: =AY10*AZ10 -> 0 | BC10: =A10 -> 0 | BD10: =AX10 -> hod | BF10: =BF9 -> 600 | BG10: =BE10*BF10 -> 0 | BI10: =G10 -> 0 | BJ10: =BD10 -> hod | BL10: =BL9 -> 800 | BM10: =BK10*BL10 -> 0 | BO10: =M10 -> 0 | BP10: =BJ10 -> hod | BR10: =BR9 -> 650 | BS10: =BQ10*BR10 -> 0 | BU10: =S10 -> 0 | BV10: =BP10 -> hod | BX10: =BX9 -> 950 | BY10: =BW10*BX10 -> 0 | CA10: =Y10 -> 0 | CB10: =BV10 -> hod | CD10: =CD9 -> 600 | CE10: =CC10*CD10 -> 0 | CG10: =A10 -> 0 | CH10: =C10+I10+O10+U10+AA10+AG10+AM10+AS10+AY10+BE10+BK10 -> 0 | CI10: =E10+K10+Q10+W10+AC10+AI10+AO10+AU10+BA10+BG10+BM10 -> 0
A11: 0 | B11: hod | D11: =D10 -> 500 | E11: =C11*D11 -> 0 | G11: =A11 -> 0 | H11: =B11 -> hod | J11: =J10 -> 400 | K11: =I11*J11 -> 0 | M11: =A11 -> 0 | N11: =H11 -> hod | P11: =P10 -> 700 | Q11: =O11*P11 -> 0 | S11: =A11 -> 0 | T11: =N11 -> hod | V11: =V10 -> 650 | W11: =U11*V11 -> 0 | Y11: =A11 -> 0 | Z11: =T11 -> hod | AB11: =AB10 -> 650 | AC11: =AA11*AB11 -> 0 | AE11: =A11 -> 0 | AF11: =Z11 -> hod | AH11: =AH10 -> 700 | AI11: =AG11*AH11 -> 0 | AK11: =G11 -> 0 | AL11: =AF11 -> hod | AN11: =AN10 -> 600 | AO11: =AM11*AN11 -> 0 | AQ11: =AK11 -> 0 | AR11: =AL11 -> hod | AT11: =AT10 -> 600 | AU11: =AS11*AT11 -> 0 | AW11: =A11 -> 0 | AX11: =AF11 -> hod | AZ11: =AZ10 -> 600 | BA11: =AY11*AZ11 -> 0 | BC11: =A11 -> 0 | BD11: =AX11 -> hod | BF11: =BF10 -> 600 | BG11: =BE11*BF11 -> 0 | BI11: =G11 -> 0 | BJ11: =BD11 -> hod | BL11: =BL10 -> 800 | BM11: =BK11*BL11 -> 0 | BO11: =M11 -> 0 | BP11: =BJ11 -> hod | BR11: =BR10 -> 650 | BS11: =BQ11*BR11 -> 0 | BU11: =S11 -> 0 | BV11: =BP11 -> hod | BX11: =BX10 -> 950 | BY11: =BW11*BX11 -> 0 | CA11: =Y11 -> 0 | CB11: =BV11 -> hod | CD11: =CD10 -> 600 | CE11: =CC11*CD11 -> 0 | CG11: =A11 -> 0 | CH11: =C11+I11+O11+U11+AA11+AG11+AM11+AS11+AY11+BE11+BK11 -> 0 | CI11: =E11+K11+Q11+W11+AC11+AI11+AO11+AU11+BA11+BG11+BM11 -> 0
A12: 0 | B12: hod | D12: =D11 -> 500 | E12: =C12*D12 -> 0 | G12: =A12 -> 0 | H12: =B12 -> hod | J12: =J11 -> 400 | K12: =I12*J12 -> 0 | M12: =A12 -> 0 | N12: =H12 -> hod | P12: =P11 -> 700 | Q12: =O12*P12 -> 0 | S12: =A12 -> 0 | T12: =N12 -> hod | V12: =V11 -> 650 | W12: =U12*V12 -> 0 | Y12: =A12 -> 0 | Z12: =T12 -> hod | AB12: =AB11 -> 650 | AC12: =AA12*AB12 -> 0 | AE12: =A12 -> 0 | AF12: =Z12 -> hod | AH12: =AH11 -> 700 | AI12: =AG12*AH12 -> 0 | AK12: =G12 -> 0 | AL12: =AF12 -> hod | AN12: =AN11 -> 600 | AO12: =AM12*AN12 -> 0 | AQ12: =AK12 -> 0 | AR12: =AL12 -> hod | AT12: =AT11 -> 600 | AU12: =AS12*AT12 -> 0 | AW12: =A12 -> 0 | AX12: =AF12 -> hod | AZ12: =AZ11 -> 600 | BA12: =AY12*AZ12 -> 0 | BC12: =A12 -> 0 | BD12: =AX12 -> hod | BF12: =BF11 -> 600 | BG12: =BE12*BF12 -> 0 | BI12: =G12 -> 0 | BJ12: =BD12 -> hod | BL12: =BL11 -> 800 | BM12: =BK12*BL12 -> 0 | BO12: =M12 -> 0 | BP12: =BJ12 -> hod | BR12: =BR11 -> 650 | BS12: =BQ12*BR12 -> 0 | BU12: =S12 -> 0 | BV12: =BP12 -> hod | BX12: =BX11 -> 950 | BY12: =BW12*BX12 -> 0 | CA12: =Y12 -> 0 | CB12: =BV12 -> hod | CD12: =CD11 -> 600 | CE12: =CC12*CD12 -> 0 | CG12: =A12 -> 0 | CH12: =C12+I12+O12+U12+AA12+AG12+AM12+AS12+AY12+BE12+BK12 -> 0 | CI12: =E12+K12+Q12+W12+AC12+AI12+AO12+AU12+BA12+BG12+BM12 -> 0
A13: 0 | B13: hod | D13: =D12 -> 500 | E13: =C13*D13 -> 0 | G13: =A13 -> 0 | H13: =B13 -> hod | J13: =J12 -> 400 | K13: =I13*J13 -> 0 | M13: =A13 -> 0 | N13: =H13 -> hod | P13: =P12 -> 700 | Q13: =O13*P13 -> 0 | S13: =A13 -> 0 | T13: =N13 -> hod | V13: =V12 -> 650 | W13: =U13*V13 -> 0 | Y13: =A13 -> 0 | Z13: =T13 -> hod | AB13: =AB12 -> 650 | AC13: =AA13*AB13 -> 0 | AE13: =A13 -> 0 | AF13: =Z13 -> hod | AH13: =AH12 -> 700 | AI13: =AG13*AH13 -> 0 | AK13: =G13 -> 0 | AL13: =AF13 -> hod | AN13: =AN12 -> 600 | AO13: =AM13*AN13 -> 0 | AQ13: =AK13 -> 0 | AR13: =AL13 -> hod | AT13: =AT12 -> 600 | AU13: =AS13*AT13 -> 0 | AW13: =A13 -> 0 | AX13: =AF13 -> hod | AZ13: =AZ12 -> 600 | BA13: =AY13*AZ13 -> 0 | BC13: =A13 -> 0 | BD13: =AX13 -> hod | BF13: =BF12 -> 600 | BG13: =BE13*BF13 -> 0 | BI13: =G13 -> 0 | BJ13: =BD13 -> hod | BL13: =BL12 -> 800 | BM13: =BK13*BL13 -> 0 | BO13: =M13 -> 0 | BP13: =BJ13 -> hod | BR13: =BR12 -> 650 | BS13: =BQ13*BR13 -> 0 | BU13: =S13 -> 0 | BV13: =BP13 -> hod | BX13: =BX12 -> 950 | BY13: =BW13*BX13 -> 0 | CA13: =Y13 -> 0 | CB13: =BV13 -> hod | CD13: =CD12 -> 600 | CE13: =CC13*CD13 -> 0 | CG13: =A13 -> 0 | CH13: =C13+I13+O13+U13+AA13+AG13+AM13+AS13+AY13+BE13+BK13 -> 0 | CI13: =E13+K13+Q13+W13+AC13+AI13+AO13+AU13+BA13+BG13+BM13 -> 0
A14: 0 | B14: hod | D14: =D13 -> 500 | E14: =C14*D14 -> 0 | G14: =A14 -> 0 | H14: =B14 -> hod | J14: =J13 -> 400 | K14: =I14*J14 -> 0 | M14: =A14 -> 0 | N14: =H14 -> hod | P14: =P13 -> 700 | Q14: =O14*P14 -> 0 | S14: =A14 -> 0 | T14: =N14 -> hod | V14: =V13 -> 650 | W14: =U14*V14 -> 0 | Y14: =A14 -> 0 | Z14: =T14 -> hod | AB14: =AB13 -> 650 | AC14: =AA14*AB14 -> 0 | AE14: =A14 -> 0 | AF14: =Z14 -> hod | AH14: =AH13 -> 700 | AI14: =AG14*AH14 -> 0 | AK14: =G14 -> 0 | AL14: =AF14 -> hod | AN14: =AN13 -> 600 | AO14: =AM14*AN14 -> 0 | AQ14: =AK14 -> 0 | AR14: =AL14 -> hod | AT14: =AT13 -> 600 | AU14: =AS14*AT14 -> 0 | AW14: =A14 -> 0 | AX14: =AF14 -> hod | AZ14: =AZ13 -> 600 | BA14: =AY14*AZ14 -> 0 | BC14: =A14 -> 0 | BD14: =AX14 -> hod | BF14: =BF13 -> 600 | BG14: =BE14*BF14 -> 0 | BI14: =G14 -> 0 | BJ14: =BD14 -> hod | BL14: =BL13 -> 800 | BM14: =BK14*BL14 -> 0 | BO14: =M14 -> 0 | BP14: =BJ14 -> hod | BR14: =BR13 -> 650 | BS14: =BQ14*BR14 -> 0 | BU14: =S14 -> 0 | BV14: =BP14 -> hod | BX14: =BX13 -> 950 | BY14: =BW14*BX14 -> 0 | CA14: =Y14 -> 0 | CB14: =BV14 -> hod | CD14: =CD13 -> 600 | CE14: =CC14*CD14 -> 0 | CG14: =A14 -> 0 | CH14: =C14+I14+O14+U14+AA14+AG14+AM14+AS14+AY14+BE14+BK14 -> 0 | CI14: =E14+K14+Q14+W14+AC14+AI14+AO14+AU14+BA14+BG14+BM14 -> 0
A15: 0 | B15: hod | D15: =D14 -> 500 | E15: =C15*D15 -> 0 | G15: =A15 -> 0 | H15: =B15 -> hod | J15: =J14 -> 400 | K15: =I15*J15 -> 0 | M15: =A15 -> 0 | N15: =H15 -> hod | P15: =P14 -> 700 | Q15: =O15*P15 -> 0 | S15: =A15 -> 0 | T15: =N15 -> hod | V15: =V14 -> 650 | W15: =U15*V15 -> 0 | Y15: =A15 -> 0 | Z15: =T15 -> hod | AB15: =AB14 -> 650 | AC15: =AA15*AB15 -> 0 | AE15: =A15 -> 0 | AF15: =Z15 -> hod | AH15: =AH14 -> 700 | AI15: =AG15*AH15 -> 0 | AK15: =G15 -> 0 | AL15: =AF15 -> hod | AN15: =AN14 -> 600 | AO15: =AM15*AN15 -> 0 | AQ15: =AK15 -> 0 | AR15: =AL15 -> hod | AT15: =AT14 -> 600 | AU15: =AS15*AT15 -> 0 | AW15: =A15 -> 0 | AX15: =AF15 -> hod | AZ15: =AZ14 -> 600 | BA15: =AY15*AZ15 -> 0 | BC15: =A15 -> 0 | BD15: =AX15 -> hod | BF15: =BF14 -> 600 | BG15: =BE15*BF15 -> 0 | BI15: =G15 -> 0 | BJ15: =BD15 -> hod | BL15: =BL14 -> 800 | BM15: =BK15*BL15 -> 0 | BO15: =M15 -> 0 | BP15: =BJ15 -> hod | BR15: =BR14 -> 650 | BS15: =BQ15*BR15 -> 0 | BU15: =S15 -> 0 | BV15: =BP15 -> hod | BX15: =BX14 -> 950 | BY15: =BW15*BX15 -> 0 | CA15: =Y15 -> 0 | CB15: =BV15 -> hod | CD15: =CD14 -> 600 | CE15: =CC15*CD15 -> 0 | CG15: =A15 -> 0 | CH15: =C15+I15+O15+U15+AA15+AG15+AM15+AS15+AY15+BE15+BK15 -> 0 | CI15: =E15+K15+Q15+W15+AC15+AI15+AO15+AU15+BA15+BG15+BM15 -> 0
A16: 0 | B16: hod | D16: =D15 -> 500 | E16: =C16*D16 -> 0 | G16: =A16 -> 0 | H16: =B16 -> hod | J16: =J15 -> 400 | K16: =I16*J16 -> 0 | M16: =A16 -> 0 | N16: =H16 -> hod | P16: =P15 -> 700 | Q16: =O16*P16 -> 0 | S16: =A16 -> 0 | T16: =N16 -> hod | V16: =V15 -> 650 | W16: =U16*V16 -> 0 | Y16: =A16 -> 0 | Z16: =T16 -> hod | AB16: =AB15 -> 650 | AC16: =AA16*AB16 -> 0 | AE16: =A16 -> 0 | AF16: =Z16 -> hod | AH16: =AH15 -> 700 | AI16: =AG16*AH16 -> 0 | AK16: =G16 -> 0 | AL16: =AF16 -> hod | AN16: =AN15 -> 600 | AO16: =AM16*AN16 -> 0 | AQ16: =AK16 -> 0 | AR16: =AL16 -> hod | AT16: =AT15 -> 600 | AU16: =AS16*AT16 -> 0 | AW16: =A16 -> 0 | AX16: =AF16 -> hod | AZ16: =AZ15 -> 600 | BA16: =AY16*AZ16 -> 0 | BC16: =A16 -> 0 | BD16: =AX16 -> hod | BF16: =BF15 -> 600 | BG16: =BE16*BF16 -> 0 | BI16: =G16 -> 0 | BJ16: =BD16 -> hod | BL16: =BL15 -> 800 | BM16: =BK16*BL16 -> 0 | BO16: =M16 -> 0 | BP16: =BJ16 -> hod | BR16: =BR15 -> 650 | BS16: =BQ16*BR16 -> 0 | BU16: =S16 -> 0 | BV16: =BP16 -> hod | BX16: =BX15 -> 950 | BY16: =BW16*BX16 -> 0 | CA16: =Y16 -> 0 | CB16: =BV16 -> hod | CD16: =CD15 -> 600 | CE16: =CC16*CD16 -> 0 | CG16: =A16 -> 0 | CH16: =C16+I16+O16+U16+AA16+AG16+AM16+AS16+AY16+BE16+BK16 -> 0 | CI16: =E16+K16+Q16+W16+AC16+AI16+AO16+AU16+BA16+BG16+BM16 -> 0
... A54: 0 | B54: hod | D54: =D53 -> 500 | E54: =C54*D54 -> 0 | G54: =A54 -> 0 | H54: =B54 -> hod | J54: =J53 -> 400 | K54: =I54*J54 -> 0 | M54: =A54 -> 0 | N54: =H54 -> hod | P54: =P53 -> 700 | Q54: =O54*P54 -> 0 | S54: =A54 -> 0 | T54: =N54 -> hod | V54: =V53 -> 650 | W54: =U54*V54 -> 0 | Y54: =A54 -> 0 | Z54: =T54 -> hod | AB54: =AB53 -> 650 | AC54: =AA54*AB54 -> 0 | AE54: =A54 -> 0 | AF54: =Z54 -> hod | AH54: =AH53 -> 700 | AI54: =AG54*AH54 -> 0 | AK54: =G54 -> 0 | AL54: =AF54 -> hod | AN54: =AN53 -> 600 | AO54: =AM54*AN54 -> 0 | AQ54: =AK54 -> 0 | AR54: =AL54 -> hod | AT54: =AT53 -> 600 | AU54: =AS54*AT54 -> 0 | AW54: =A54 -> 0 | AX54: =AF54 -> hod | AZ54: =AZ53 -> 600 | BA54: =AY54*AZ54 -> 0 | BC54: =A54 -> 0 | BD54: =AX54 -> hod | BF54: =BF53 -> 600 | BG54: =BE54*BF54 -> 0 | BI54: =G54 -> 0 | BJ54: =BD54 -> hod | BL54: =BL53 -> 800 | BM54: =BK54*BL54 -> 0 | BO54: =M54 -> 0 | BP54: =BJ54 -> hod | BR54: =BR53 -> 650 | BS54: =BQ54*BR54 -> 0 | BU54: =S54 -> 0 | BV54: =BP54 -> hod | BX54: =BX53 -> 950 | BY54: =BW54*BX54 -> 0 | CA54: =Y54 -> 0 | CB54: =BV54 -> hod | CD54: =CD53 -> 600 | CE54: =CC54*CD54 -> 0 | CG54: =A54 -> 0 | CH54: =C54+I54+O54+U54+AA54+AG54+AM54+AS54+AY54+BE54+BK54 -> 0 | CI54: =E54+K54+Q54+W54+AC54+AI54+AO54+AU54+BA54+BG54+BM54 -> 0
A55: Celkem | B55: x | C55: =SUM(C4:C54) -> 0 | D55: x | E55: =SUM(E4:E54) -> 0 | G55: =A55 -> Celkem | H55: x | I55: =SUM(I4:I54) -> 0 | J55: x | K55: =SUM(K4:K54) -> 0 | M55: =A55 -> Celkem | N55: x | O55: =SUM(O4:O54) -> 0 | P55: x | Q55: =SUM(Q4:Q54) -> 0 | S55: Celkem | T55: x | U55: =SUM(U4:U54) -> 0 | V55: x | W55: =SUM(W4:W54) -> 0 | Y55: Celkem | Z55: x | AA55: =SUM(AA4:AA54) -> 0 | AB55: x | AC55: =SUM(AC4:AC54) -> 0 | AE55: =Y55 -> Celkem | AF55: x | AG55: =SUM(AG4:AG54) -> 0 | AH55: x | AI55: =SUM(AI4:AI54) -> 0 | AK55: =AE55 -> Celkem | AL55: x | AM55: =SUM(AM4:AM54) -> 0 | AN55: x | AO55: =SUM(AO4:AO54) -> 0 | AQ55: =AK55 -> Celkem | AR55: x | AS55: =SUM(AS4:AS54) -> 0 | AT55: x | AU55: =SUM(AU4:AU54) -> 0 | AW55: =Y55 -> Celkem | AX55: x | AY55: =SUM(AY4:AY54) -> 0 | AZ55: x | BA55: =SUM(BA4:BA54) -> 0 | BC55: Celkem | BD55: x | BE55: =SUM(BE4:BE54) -> 0 | BF55: x | BG55: =SUM(BG4:BG54) -> 0 | BI55: Celkem | BJ55: x | BK55: =SUM(BK4:BK54) -> 0 | BL55: x | BM55: =SUM(BM4:BM54) -> 0 | BO55: Celkem | BP55: x | BQ55: =SUM(BQ4:BQ54) -> 0 | BR55: x | BS55: =SUM(BS4:BS54) -> 0 | BU55: Celkem | BV55: x | BW55: =SUM(BW4:BW54) -> 0 | BX55: x | BY55: =SUM(BY4:BY54) -> 0 | CA55: Celkem | CB55: x | CC55: =SUM(CC4:CC54) -> 0 | CD55: x | CE55: =SUM(CE4:CE54) -> 0 | CH55: =SUM(CH4:CH54) -> 0 | CI55: =SUM(CI4:CI54) -> 0
A67: =A3 -> Martin | B67: =E55 -> 0
A68: =G3 -> Vlaďka | B68: =K55 -> 0
A69: =M3 | B69: =Q55 -> 0
A70: =S3 | B70: =W55 -> 0
A71: =Y3 | B71: =AC55 -> 0
A72: =AE3 | B72: =AI55 -> 0
A73: =AK3 | B73: =AO55 -> 0
A74: =AQ3 | B74: =AU55 -> 0
A75: =AW3 | B75: =BA55 -> 0
A76: =BC3 | B76: =BG55 -> 0
A77: =BI3 | B77: =BM55 -> 0
A78: =BO3 | B78: =BS55 -> 0
A79: =BU3 | B79: =BY55 -> 0
A80: =CA3 | B80: =CE55 -> 0
A81: =A55 -> Celkem | B81: =SUM(B67:B80) -> 0

Sheet služby
A1: Služby | B1: ='zadání'!D18 -> FALSE
Y2: Rozpis dní: | AI2: Konec
A3: Doprava | B3: MJ | C3: počet MJ | D3: Kč/MJ | E3: Kč celkem | F3: =B1 -> FALSE | G3: Kč celkem | I3: Mechanizace | J3: MJ | K3: počet MJ | L3: Kč/MJ | M3: Kč celkem | N3: =B1 -> FALSE | O3: Kč celkem | Q3: xxx | R3: MJ | S3: počet MJ | T3: Kč/MJ | U3: Kč celkem | V3: =B1 -> FALSE | W3: Kč celkem
A4: Auto | B4: km | D4: 9 | E4: =C4*D4 -> 0 | F4: =F3 -> FALSE | G4: =IF(F4,E4*1.21,E4) -> 0 | I4: Formátovací pila | J4: h | L4: =IF(K4 > 0,VLOOKUP(I4,'Ceník mechanizace'!$B$8:$D$31,3,0),0) -> 0 | M4: =K4*L4 -> 0 | N4: =N3 -> FALSE | O4: =IF(N4,M4*1.21,M4) -> 0 | U4: =S4*T4 -> 0 | V4: =V3 -> FALSE | W4: =IF(V4,U4*1.21,U4) -> 0
A5: Vozík | B5: km | D5: 3 | E5: =C5*D5 -> 0 | F5: =F4 -> FALSE | G5: =IF(F5,E5*1.21,E5) -> 0 | I5: Hoblovka | J5: h | L5: =IF(K5 > 0,VLOOKUP(I5,'Ceník mechanizace'!$B$8:$D$31,3,0),0) -> 0 | M5: =K5*L5 -> 0 | N5: =N4 -> FALSE | O5: =IF(N5,M5*1.21,M5) -> 0 | U5: =S5*T5 -> 0 | V5: =V4 -> FALSE | W5: =IF(V5,U5*1.21,U5) -> 0
A6: Vozík | B6: akce | C6: =IF(C5 > 0, 1, 0) -> 0 | D6: 200 | E6: =C6*D6 -> 0 | F6: =F5 -> FALSE | G6: =IF(F6,E6*1.21,E6) -> 0 | I6: Frézka | J6: h | L6: =IF(K6 > 0,VLOOKUP(I6,'Ceník mechanizace'!$B$8:$D$31,3,0),0) -> 0 | M6: =K6*L6 -> 0 | N6: =N5 -> FALSE | O6: =IF(N6,M6*1.21,M6) -> 0 | U6: =S6*T6 -> 0 | V6: =V5 -> FALSE | W6: =IF(V6,U6*1.21,U6) -> 0
A7: Čas | B7: h | D7: 250 | E7: =C7*D7 -> 0 | F7: =F6 -> FALSE | G7: =IF(F7,E7*1.21,E7) -> 0 | I7: Excentrická bruska | J7: h | L7: =IF(K7 > 0,VLOOKUP(I7,'Ceník mechanizace'!$B$8:$D$31,3,0),0) -> 0 | M7: =K7*L7 -> 0 | N7: =N6 -> FALSE | O7: =IF(N7,M7*1.21,M7) -> 0 | U7: =S7*T7 -> 0 | V7: =V6 -> FALSE | W7: =IF(V7,U7*1.21,U7) -> 0
E8: =C8*D8 -> 0 | F8: =F7 -> FALSE | G8: =IF(F8,E8*1.21,E8) -> 0 | J8: h | L8: =IF(K8 > 0,VLOOKUP(I8,'Ceník mechanizace'!$B$8:$D$31,3,0),0) -> 0 | M8: =K8*L8 -> 0 | N8: =N7 -> FALSE | O8: =IF(N8,M8*1.21,M8) -> 0 | U8: =S8*T8 -> 0 | V8: =V7 -> FALSE | W8: =IF(V8,U8*1.21,U8) -> 0
E9: =C9*D9 -> 0 | F9: =F8 -> FALSE | G9: =IF(F9,E9*1.21,E9) -> 0 | J9: h | L9: =IF(K9 > 0,VLOOKUP(I9,'Ceník mechanizace'!$B$8:$D$31,3,0),0) -> 0 | M9: =K9*L9 -> 0 | N9: =N8 -> FALSE | O9: =IF(N9,M9*1.21,M9) -> 0 | U9: =S9*T9 -> 0 | V9: =V8 -> FALSE | W9: =IF(V9,U9*1.21,U9) -> 0
E10: =C10*D10 -> 0 | F10: =F9 -> FALSE | G10: =IF(F10,E10*1.21,E10) -> 0 | J10: h | L10: =IF(K10 > 0,VLOOKUP(I10,'Ceník mechanizace'!$B$8:$D$31,3,0),0) -> 0 | M10: =K10*L10 -> 0 | N10: =N9 -> FALSE | O10: =IF(N10,M10*1.21,M10) -> 0 | U10: =S10*T10 -> 0 | V10: =V9 -> FALSE | W10: =IF(V10,U10*1.21,U10) -> 0
E11: =C11*D11 -> 0 | F11: =F10 -> FALSE | G11: =IF(F11,E11*1.21,E11) -> 0 | J11: h | L11: =IF(K11 > 0,VLOOKUP(I11,'Ceník mechanizace'!$B$8:$D$31,3,0),0) -> 0 | M11: =K11*L11 -> 0 | N11: =N10 -> FALSE | O11: =IF(N11,M11*1.21,M11) -> 0 | U11: =S11*T11 -> 0 | V11: =V10 -> FALSE | W11: =IF(V11,U11*1.21,U11) -> 0
E12: =C12*D12 -> 0 | F12: =F11 -> FALSE | G12: =IF(F12,E12*1.21,E12) -> 0 | I12: Odsávání | J12: h | K12: =K4+K5+K6 -> 0 | L12: =IF(K12 > 0,VLOOKUP(I12,'Ceník mechanizace'!$B$8:$D$31,3,0),0) -> 0 | M12: =K12*L12 -> 0 | N12: =N11 -> FALSE | O12: =IF(N12,M12*1.21,M12) -> 0 | U12: =S12*T12 -> 0 | V12: =V11 -> FALSE | W12: =IF(V12,U12*1.21,U12) -> 0
E13: =C13*D13 -> 0 | F13: =F12 -> FALSE | G13: =IF(F13,E13*1.21,E13) -> 0 | I13: Vysavač | J13: h | K13: =K7 | L13: =IF(K13 > 0,VLOOKUP(I13,'Ceník mechanizace'!$B$8:$D$31,3,0),0) -> 0 | M13: =K13*L13 -> 0 | N13: =N12 -> FALSE | O13: =IF(N13,M13*1.21,M13) -> 0 | V13: FALSE
A14: Celkem | B14: x | C14: x | D14: x | E14: =SUM(E4:E13) -> 0 | F14: X | G14: =SUM(G4:G13) -> 0 | I14: =A14 -> Celkem | J14: x | K14: x | L14: x | M14: =SUM(M4:M13) -> 0 | N14: X | O14: =SUM(O4:O13) -> 0 | Q14: =A14 -> Celkem | R14: x | S14: x | T14: x | U14: =SUM(U4:U11) -> 0 | V14: X | W14: =SUM(W4:W13) -> 0
A16: xxx | B16: MJ | C16: počet MJ | D16: Kč/MJ | E16: Kč celkem | F16: =B1 -> FALSE | G16: Kč celkem | I16: xxx | J16: MJ | K16: počet MJ | L16: Kč/MJ | M16: Kč celkem | N16: =B1 -> FALSE | O16: Kč celkem | Q16: xxx | R16: MJ | S16: počet MJ | T16: Kč/MJ | U16: Kč celkem | V16: =B1 -> FALSE | W16: Kč celkem | Y16: Sleva | Z16: MJ | AA16: počet MJ | AB16: Kč/MJ | AC16: Kč celkem | AD16: =B1 -> FALSE | AE16: Kč celkem
E17: =C17*D17 -> 0 | F17: =F16 -> FALSE | G17: =IF(F17,E17*1.21,E17) -> 0 | M17: =K17*L17 -> 0 | N17: =N16 -> FALSE | O17: =IF(N17,M17*1.21,M17) -> 0 | U17: =S17*T17 -> 0 | V17: =V16 -> FALSE | W17: =IF(V17,U17*1.21,U17) -> 0 | AC17: =AA17*AB17 -> 0 | AD17: =AD16 -> FALSE | AE17: =IF(AD17,AC17*1.21,AC17) -> 0
E18: =C18*D18 -> 0 | F18: =F17 -> FALSE | G18: =IF(F18,E18*1.21,E18) -> 0 | M18: =K18*L18 -> 0 | N18: =N17 -> FALSE | O18: =IF(N18,M18*1.21,M18) -> 0 | U18: =S18*T18 -> 0 | V18: =V17 -> FALSE | W18: =IF(V18,U18*1.21,U18) -> 0 | AC18: =AA18*AB18 -> 0 | AD18: =AD17 -> FALSE | AE18: =IF(AD18,AC18*1.21,AC18) -> 0
E19: =C19*D19 -> 0 | F19: =F18 -> FALSE | G19: =IF(F19,E19*1.21,E19) -> 0 | M19: =K19*L19 -> 0 | N19: =N18 -> FALSE | O19: =IF(N19,M19*1.21,M19) -> 0 | U19: =S19*T19 -> 0 | V19: =V18 -> FALSE | W19: =IF(V19,U19*1.21,U19) -> 0 | AC19: =AA19*AB19 -> 0 | AD19: =AD18 -> FALSE | AE19: =IF(AD19,AC19*1.21,AC19) -> 0
E20: =C20*D20 -> 0 | F20: =F19 -> FALSE | G20: =IF(F20,E20*1.21,E20) -> 0 | M20: =K20*L20 -> 0 | N20: =N19 -> FALSE | O20: =IF(N20,M20*1.21,M20) -> 0 | U20: =S20*T20 -> 0 | V20: =V19 -> FALSE | W20: =IF(V20,U20*1.21,U20) -> 0 | AC20: =AA20*AB20 -> 0 | AD20: =AD19 -> FALSE | AE20: =IF(AD20,AC20*1.21,AC20) -> 0
E21: =C21*D21 -> 0 | F21: =F20 -> FALSE | G21: =IF(F21,E21*1.21,E21) -> 0 | M21: =K21*L21 -> 0 | N21: =N20 -> FALSE | O21: =IF(N21,M21*1.21,M21) -> 0 | U21: =S21*T21 -> 0 | V21: =V20 -> FALSE | W21: =IF(V21,U21*1.21,U21) -> 0 | AC21: =AA21*AB21 -> 0 | AD21: =AD20 -> FALSE | AE21: =IF(AD21,AC21*1.21,AC21) -> 0
E22: =C22*D22 -> 0 | F22: =F21 -> FALSE | G22: =IF(F22,E22*1.21,E22) -> 0 | M22: =K22*L22 -> 0 | N22: =N21 -> FALSE | O22: =IF(N22,M22*1.21,M22) -> 0 | U22: =S22*T22 -> 0 | V22: =V21 -> FALSE | W22: =IF(V22,U22*1.21,U22) -> 0 | AC22: =AA22*AB22 -> 0 | AD22: =AD21 -> FALSE | AE22: =IF(AD22,AC22*1.21,AC22) -> 0
E23: =C23*D23 -> 0 | F23: =F22 -> FALSE | G23: =IF(F23,E23*1.21,E23) -> 0 | M23: =K23*L23 -> 0 | N23: =N22 -> FALSE | O23: =IF(N23,M23*1.21,M23) -> 0 | U23: =S23*T23 -> 0 | V23: =V22 -> FALSE | W23: =IF(V23,U23*1.21,U23) -> 0 | AC23: =AA23*AB23 -> 0 | AD23: =AD22 -> FALSE | AE23: =IF(AD23,AC23*1.21,AC23) -> 0
E24: =C24*D24 -> 0 | F24: =F23 -> FALSE | G24: =IF(F24,E24*1.21,E24) -> 0 | M24: =K24*L24 -> 0 | N24: =N23 -> FALSE | O24: =IF(N24,M24*1.21,M24) -> 0 | U24: =S24*T24 -> 0 | V24: =V23 -> FALSE | W24: =IF(V24,U24*1.21,U24) -> 0 | AC24: =AA24*AB24 -> 0 | AD24: =AD23 -> FALSE | AE24: =IF(AD24,AC24*1.21,AC24) -> 0
E25: =C25*D25 -> 0 | F25: =F24 -> FALSE | G25: =IF(F25,E25*1.21,E25) -> 0 | M25: =K25*L25 -> 0 | N25: =N24 -> FALSE | O25: =IF(N25,M25*1.21,M25) -> 0 | U25: =S25*T25 -> 0 | V25: =V24 -> FALSE | W25: =IF(V25,U25*1.21,U25) -> 0 | AC25: =AA25*AB25 -> 0 | AD25: =AD24 -> FALSE | AE25: =IF(AD25,AC25*1.21,AC25) -> 0
E26: =C26*D26 -> 0 | F26: =F25 -> FALSE | G26: =IF(F26,E26*1.21,E26) -> 0 | M26: =K26*L26 -> 0 | N26: =N25 -> FALSE | O26: =IF(N26,M26*1.21,M26) -> 0 | U26: =S26*T26 -> 0 | V26: =V25 -> FALSE | W26: =IF(V26,U26*1.21,U26) -> 0 | AC26: =AA26*AB26 -> 0 | AD26: =AD25 -> FALSE | AE26: =IF(AD26,AC26*1.21,AC26) -> 0
E27: =C27*D27 -> 0 | F27: =F26 -> FALSE | G27: =IF(F27,E27*1.21,E27) -> 0 | M27: =K27*L27 -> 0 | N27: =N25 -> FALSE | O27: =IF(N27,M27*1.21,M27) -> 0 | U27: =S27*T27 -> 0 | V27: =V25 -> FALSE | W27: =IF(V27,U27*1.21,U27) -> 0 | AC27: =AA27*AB27 -> 0 | AE27: =IF(AD27,AC27*1.21,AC27) -> 0
A28: =A14 -> Celkem | B28: x | C28: x | D28: x | E28: =SUM(E17:E27) -> 0 | F28: X | G28: =SUM(G17:G27) -> 0 | I28: =A14 -> Celkem | J28: x | K28: x | L28: x | M28: =SUM(M17:M27) -> 0 | N28: X | O28: =SUM(O17:O27) -> 0 | Q28: =A28 -> Celkem | R28: x | S28: x | T28: x | U28: =SUM(U17:U27) -> 0 | V28: X | W28: =SUM(W17:W27) -> 0 | Y28: =I28 -> Celkem | Z28: x | AA28: x | AB28: x | AC28: =SUM(AC17:AC27) -> 0 | AD28: X | AE28: =SUM(AE17:AE27) -> 0
A30: =A3 -> Doprava | B30: =IF(B1,G14,E14) -> 0 | I30: xxx | J30: MJ | K30: počet MJ | L30: Kč/MJ | M30: Kč celkem | N30: =B1 -> FALSE | O30: Kč celkem | Q30: Ostatní | R30: MJ | S30: počet MJ | T30: Kč/MJ | U30: Kč celkem | V30: =B1 -> FALSE | W30: Kč celkem
A31: =I3 -> Mechanizace | B31: =IF(B1,O14,M14) -> 0 | M31: =K31*L31 -> 0 | N31: =N30 -> FALSE | O31: =IF(N31,M31*1.21,M31) -> 0 | Q31: Ruční nářadí | R31: akce/os. | T31: 100 | U31: =S31*T31 -> 0 | V31: =V30 -> FALSE | W31: =IF(V31,U31*1.21,U31) -> 0
A32: =Q3 -> xxx | B32: =IF(B1,W14,U14) -> 0 | M32: =K32*L32 -> 0 | N32: =N31 -> FALSE | O32: =IF(N32,M32*1.21,M32) -> 0 | U32: =S32*T32 -> 0 | V32: =V31 -> FALSE | W32: =IF(V32,U32*1.21,U32) -> 0 | Y32: Doprava | Z32: km | AA32: =S14 -> x | AB32: =IF(T14,12,0) -> #VALUE!
A33: =A16 -> xxx | B33: =IF(B1,G28,E28) -> 0 | M33: =K33*L33 -> 0 | N33: =N32 -> FALSE | O33: =IF(N33,M33*1.21,M33) -> 0 | U33: =S33*T33 -> 0 | V33: =V32 -> FALSE | W33: =IF(V33,U33*1.21,U33) -> 0 | Y33: Čas | Z33: h | AA33: =S15/2 -> 0 | AB33: =T15
A34: =I16 -> xxx | B34: =IF(T8,5,0) -> 0 | M34: =K34*L34 -> 0 | N34: =N33 -> FALSE | O34: =IF(N34,M34*1.21,M34) -> 0 | U34: =S34*T34 -> 0 | V34: =V33 -> FALSE | W34: =IF(V34,U34*1.21,U34) -> 0
A35: =Q16 -> xxx | B35: =IF(B1,W28,U28) -> 0 | M35: =K35*L35 -> 0 | N35: =N34 -> FALSE | O35: =IF(N35,M35*1.21,M35) -> 0 | U35: =S35*T35 -> 0 | V35: =V34 -> FALSE | W35: =IF(V35,U35*1.21,U35) -> 0
A36: =I30 -> xxx | B36: =IF(B1,O39,M39) -> 0 | M36: =K36*L36 -> 0 | N36: =N35 -> FALSE | O36: =IF(N36,M36*1.21,M36) -> 0 | U36: =S36*T36 -> 0 | V36: =V35 -> FALSE | W36: =IF(V36,U36*1.21,U36) -> 0
A37: =Q30 -> Ostatní | B37: =IF(B1,W39,U39) -> 0 | M37: =K37*L37 -> 0 | N37: =N36 -> FALSE | O37: =IF(N37,M37*1.21,M37) -> 0 | U37: =S37*T37 -> 0 | V37: =V36 -> FALSE | W37: =IF(V37,U37*1.21,U37) -> 0
A38: =Y16 -> Sleva | B38: =IF(B1,AE28,AC28) -> 0 | N38: =N37 -> FALSE | V38: =V37 -> FALSE
A39: =A14 -> Celkem | B39: =SUM(B30:B37) -> 0 | I39: =A28 -> Celkem | J39: x | K39: x | L39: x | M39: =SUM(M31:M37) -> 0 | N39: X | O39: =SUM(O31:O37) -> 0 | Q39: =I28 -> Celkem | R39: x | S39: x | T39: x | U39: =SUM(U31:U37) -> 0 | V39: X | W39: =SUM(W31:W37) -> 0

Sheet materiál
A1: Materiál | B1: ='zadání'!D18 -> FALSE
A3: Dřevo | B3: MJ | C3: počet MJ | D3: Kč/MJ | E3: Kč celkem | F3: =B1 -> FALSE | G3: Kč Celkem | I3: Spojovací materiál | J3: MJ | K3: počet MJ | L3: Kč/MJ | M3: Kč celkem | N3: =B1 -> FALSE | O3: Kč Celkem | Q3: Povrchovka | R3: MJ | S3: počet MJ | T3: Kč/MJ | U3: Kč celkem | V3: =B1 -> FALSE | W3: Kč Celkem | Y3: Materiál 12% DPH | Z3: MJ | AA3: počet MJ | AB3: Kč/MJ | AC3: Kč celkem | AD3: =B1 -> FALSE | AE3: Kč Celkem
A4: Řezivo | B4: Kč | C4: 1 | D4: ='Výpočet dřeva'!O56 -> 0 | E4: =C4*D4 -> 0 | F4: =F3 -> FALSE | G4: =IF(F4,E4*1.21,E4) -> 0 | I4: Lepidlo | J4: akce | K4: 1 | L4: =IF('materiál'!K4 > 0, VLOOKUP(I4,'Ceník - ostatní materiál'!$B$3:$D$40,3,0),0) -> 50 | M4: =K4*L4 -> 50 | N4: =N3 -> FALSE | O4: =IF(N4,M4*1.21,M4) -> 50 | Q4: Osmo | R4: m2 | S4: =SUMIF('Výpočet dřeva'!$F$2:$F$50,1,'Výpočet dřeva'!$H$2:$H$50) * 2 * 1.1 -> 0 | T4: =IF('materiál'!S4 > 0,VLOOKUP(Q4,'Ceník - ostatní materiál'!$B$42:$D$53,3,0),0) -> 0 | U4: =S4*T4 -> 0 | V4: =V3 -> FALSE | W4: =IF(V4,U4*1.21,U4) -> 0 | AC4: =AA4*AB4 -> 0 | AD4: =AD3 -> FALSE | AE4: =IF(AD4,AC4*1.21,AC4) -> 0
E5: =C5*D5 -> 0 | F5: =F4 -> FALSE | G5: =IF(F5,E5*1.21,E5) -> 0 | L5: =IF('materiál'!K5 > 0, VLOOKUP(I5,'Ceník - ostatní materiál'!$B$3:$D$40,3,0),0) -> 0 | M5: =K5*L5 -> 0 | N5: =N4 -> FALSE | O5: =IF(N5,M5*1.21,M5) -> 0 | R5: m2 | T5: =IF('materiál'!S5 > 0,VLOOKUP(Q5,'Ceník - ostatní materiál'!$B$42:$D$53,3,0),0) -> 0 | U5: =S5*T5 -> 0 | V5: =V4 -> FALSE | W5: =IF(V5,U5*1.21,U5) -> 0 | AC5: =AA5*AB5 -> 0 | AD5: =AD4 -> FALSE | AE5: =IF(AD5,AC5*1.21,AC5) -> 0
E6: =C6*D6 -> 0 | F6: =F5 -> FALSE | G6: =IF(F6,E6*1.21,E6) -> 0 | L6: =IF('materiál'!K6 > 0, VLOOKUP(I6,'Ceník - ostatní materiál'!$B$3:$D$40,3,0),0) -> 0 | M6: =K6*L6 -> 0 | N6: =N5 -> FALSE | O6: =IF(N6,M6*1.21,M6) -> 0 | R6: m2 | T6: =IF('materiál'!S6 > 0,VLOOKUP(Q6,'Ceník - ostatní materiál'!$B$42:$D$53,3,0),0) -> 0 | U6: =S6*T6 -> 0 | V6: =V5 -> FALSE | W6: =IF(V6,U6*1.21,U6) -> 0 | AC6: =AA6*AB6 -> 0 | AD6: =AD5 -> FALSE | AE6: =IF(AD6,AC6*1.21,AC6) -> 0
E7: =C7*D7 -> 0 | F7: =F6 -> FALSE | G7: =IF(F7,E7*1.21,E7) -> 0 | L7: =IF('materiál'!K7 > 0, VLOOKUP(I7,'Ceník - ostatní materiál'!$B$3:$D$40,3,0),0) -> 0 | M7: =K7*L7 -> 0 | N7: =N6 -> FALSE | O7: =IF(N7,M7*1.21,M7) -> 0 | R7: m2 | T7: =IF('materiál'!S7 > 0,VLOOKUP(Q7,'Ceník - ostatní materiál'!$B$42:$D$53,3,0),0) -> 0 | U7: =S7*T7 -> 0 | V7: =V6 -> FALSE | W7: =IF(V7,U7*1.21,U7) -> 0 | AC7: =AA7*AB7 -> 0 | AD7: =AD6 -> FALSE | AE7: =IF(AD7,AC7*1.21,AC7) -> 0
E8: =C8*D8 -> 0 | F8: =F7 -> FALSE | G8: =IF(F8,E8*1.21,E8) -> 0 | L8: =IF('materiál'!K8 > 0, VLOOKUP(I8,'Ceník - ostatní materiál'!$B$3:$D$40,3,0),0) -> 0 | M8: =K8*L8 -> 0 | N8: =N7 -> FALSE | O8: =IF(N8,M8*1.21,M8) -> 0 | R8: m2 | T8: =IF('materiál'!S8 > 0,VLOOKUP(Q8,'Ceník - ostatní materiál'!$B$42:$D$53,3,0),0) -> 0 | U8: =S8*T8 -> 0 | V8: =V7 -> FALSE | W8: =IF(V8,U8*1.21,U8) -> 0 | AC8: =AA8*AB8 -> 0 | AD8: =AD7 -> FALSE | AE8: =IF(AD8,AC8*1.21,AC8) -> 0
E9: =C9*D9 -> 0 | F9: =F8 -> FALSE | G9: =IF(F9,E9*1.21,E9) -> 0 | L9: =IF('materiál'!K9 > 0, VLOOKUP(I9,'Ceník - ostatní materiál'!$B$3:$D$40,3,0),0) -> 0 | M9: =K9*L9 -> 0 | N9: =N8 -> FALSE | O9: =IF(N9,M9*1.21,M9) -> 0 | R9: m2 | T9: =IF('materiál'!S9 > 0,VLOOKUP(Q9,'Ceník - ostatní materiál'!$B$42:$D$53,3,0),0) -> 0 | U9: =S9*T9 -> 0 | V9: =V8 -> FALSE | W9: =IF(V9,U9*1.21,U9) -> 0 | AC9: =AA9*AB9 -> 0 | AD9: =AD8 -> FALSE | AE9: =IF(AD9,AC9*1.21,AC9) -> 0
A10: Celkem | B10: x | C10: =SUM(C4:C9) -> 1 | D10: x | E10: =SUM(E4:E9) -> 0 | F10: X | G10: =SUM(G3:G9) -> 0 | I10: =A10 -> Celkem | J10: x | K10: x | L10: x | M10: =SUM(M4:M9) -> 50 | N10: X | O10: =SUM(O3:O9) -> 50 | Q10: =A10 -> Celkem | R10: x | S10: x | T10: x | U10: =SUM(U4:U9) -> 0 | V10: X | W10: =SUM(W3:W9) -> 0 | Y10: =I10 -> Celkem | Z10: x | AA10: x | AB10: x | AC10: =SUM(AC4:AC9) -> 0 | AD10: X | AE10: =SUM(AE3:AE9) -> 0
A12: =A3 -> Dřevo | B12: =IF(B1,G10,E10) -> 0
A13: =I3 -> Spojovací materiál | B13: =IF(B1,O10,M10) -> 50
A14: =Q3 -> Povrchovka | B14: =IF(B1,W10,U10) -> 0
A15: =Y3 -> Materiál 12% DPH | B15: =IF(B1,AE10,AC10) -> 0
A16: Rostliny | B16: =SUM(B12:B14) -> 50
A18: Brusný materiál | B18: MJ | C18: počet MJ | D18: Kč/MJ | E18: Kč celkem | F18: =B1 -> FALSE | G18: Kč Celkem | I18: xxx | J18: MJ | K18: počet MJ | L18: Kč/MJ | M18: Kč celkem | N18: =B1 -> FALSE | O18: Kč Celkem | Q18: xxx | R18: MJ | S18: počet MJ | T18: Kč/MJ | U18: Kč celkem | V18: =B1 -> FALSE | W18: Kč Celkem
A19: Brusný výsek 150 mm | B19: ks | D19: =IF('materiál'!C19 > 0,VLOOKUP(A19,'Ceník - ostatní materiál'!$B$55:$D$66,3,0),0) -> 0 | E19: =C19*D19 -> 0 | F19: =F18 -> FALSE | G19: =IF(F19,E19*1.21,E19) -> 0 | M19: =K19*L19 -> 0 | N19: =N18 -> FALSE | O19: =IF(N19,M19*1.21,M19) -> 0 | U19: =S19*T19 -> 0 | V19: =V18 -> FALSE | W19: =IF(V19,U19*1.21,U19) -> 0
A20: Brusný výsek houbička | B20: ks | D20: =IF('materiál'!C20 > 0,VLOOKUP(A20,'Ceník - ostatní materiál'!$B$55:$D$66,3,0),0) -> 0 | E20: =C20*D20 -> 0 | F20: =F19 -> FALSE | G20: =IF(F20,E20*1.21,E20) -> 0 | M20: =K20*L20 -> 0 | N20: =N19 -> FALSE | O20: =IF(N20,M20*1.21,M20) -> 0 | U20: =S20*T20 -> 0 | V20: =V19 -> FALSE | W20: =IF(V20,U20*1.21,U20) -> 0
A21: Brusný pás | B21: ks | D21: =IF('materiál'!C21 > 0,VLOOKUP(A21,'Ceník - ostatní materiál'!$B$55:$D$66,3,0),0) -> 0 | E21: =C21*D21 -> 0 | F21: =F20 -> FALSE | G21: =IF(F21,E21*1.21,E21) -> 0 | M21: =K21*L21 -> 0 | N21: =N20 -> FALSE | O21: =IF(N21,M21*1.21,M21) -> 0 | U21: =S21*T21 -> 0 | V21: =V20 -> FALSE | W21: =IF(V21,U21*1.21,U21) -> 0
A22: Houba na povrchovku | B22: ks | D22: =IF('materiál'!C22 > 0,VLOOKUP(A22,'Ceník - ostatní materiál'!$B$55:$D$66,3,0),0) -> 0 | E22: =C22*D22 -> 0 | F22: =F21 -> FALSE | G22: =IF(F22,E22*1.21,E22) -> 0 | M22: =K22*L22 -> 0 | N22: =N21 -> FALSE | O22: =IF(N22,M22*1.21,M22) -> 0 | U22: =S22*T22 -> 0 | V22: =V21 -> FALSE | W22: =IF(V22,U22*1.21,U22) -> 0
B23: ks | D23: =IF('materiál'!C23 > 0,VLOOKUP(A23,'Ceník - ostatní materiál'!$B$55:$D$66,3,0),0) -> 0 | E23: =C23*D23 -> 0 | F23: =F22 -> FALSE | G23: =IF(F23,E23*1.21,E23) -> 0 | M23: =K23*L23 -> 0 | N23: =N22 -> FALSE | O23: =IF(N23,M23*1.21,M23) -> 0 | U23: =S23*T23 -> 0 | V23: =V22 -> FALSE | W23: =IF(V23,U23*1.21,U23) -> 0
B24: ks | D24: =IF('materiál'!C24 > 0,VLOOKUP(A24,'Ceník - ostatní materiál'!$B$55:$D$66,3,0),0) -> 0 | E24: =C24*D24 -> 0 | F24: =F23 -> FALSE | G24: =IF(F24,E24*1.21,E24) -> 0 | M24: =K24*L24 -> 0 | N24: =N23 -> FALSE | O24: =IF(N24,M24*1.21,M24) -> 0 | U24: =S24*T24 -> 0 | V24: =V23 -> FALSE | W24: =IF(V24,U24*1.21,U24) -> 0
B25: ks | D25: =IF('materiál'!C25 > 0,VLOOKUP(A25,'Ceník - ostatní materiál'!$B$55:$D$66,3,0),0) -> 0 | E25: =C25*D25 -> 0 | F25: =F24 -> FALSE | G25: =IF(F25,E25*1.21,E25) -> 0 | M25: =K25*L25 -> 0 | N25: =N24 -> FALSE | O25: =IF(N25,M25*1.21,M25) -> 0 | U25: =S25*T25 -> 0 | V25: =V24 -> FALSE | W25: =IF(V25,U25*1.21,U25) -> 0
A26: Celkem | B26: x | C26: x | D26: x | E26: =SUM(E19:E25) -> 0 | F26: X | G26: =SUM(G19:G25) -> 0 | I26: =A26 -> Celkem | J26: x | K26: x | L26: x | M26: =SUM(M19:M25) -> 0 | N26: X | O26: =SUM(O19:O25) -> 0 | Q26: =A26 -> Celkem | R26: x | S26: x | T26: x | U26: =SUM(U19:U25) -> 0 | V26: X | W26: =SUM(W19:W25) -> 0
A28: =A18 -> Brusný materiál | B28: =IF(B1,G26,E26) -> 0
A29: =I18 -> xxx | B29: =IF(B1,O26,M26) -> 0
A30: =Q18 -> xxx | B30: =IF(B1,W26,U26) -> 0
A31: Technický | B31: =SUM(B28:B30) -> 0
A33: =A16 -> Rostliny | B33: =B16 -> 50
A34: =A31 -> Technický | B34: =B31 -> 0
A35: =A26 -> Celkem | B35: =B34+B33 -> 50

Sheet finance
A1: Finance
A3: Režijní náklady | B3: MJ | C3: počet MJ | D3: Kč/MJ | E3: Kč celkem
A4: Kalkulace | B4: hod | C4: =SUM(F4:R4) -> 0 | D4: 600 | E4: =C4*D4 -> 0
A5: Fakturace | B5: hod | C5: 0.5 | D5: 600 | E5: =C5*D5 -> 300
A6: Návrh projektu | B6: hod | C6: =SUM(F6:R6) -> 0 | D6: 600 | E6: =C6*D6 -> 0
E7: =C7*D7 -> 0
E8: =C8*D8 -> 0
E9: =C9*D9 -> 0
E10: =C10*D10 -> 0
A11: Celkem | B11: x | C11: =SUM(C4:C10) -> 0.5 | D11: x | E11: =SUM(E4:E10) -> 300
A13: =A3 -> Režijní náklady | B13: =E11 -> 300
A14: =G3 | B14: =K11
A15: =M3 | B15: =Q11
A16: =A11 -> Celkem | B16: =SUM(B13:B15) -> 300

Sheet součty
A1: Jednicové náklady
A3: ='materiál'!A1 -> Materiál | B3: MJ | C3: počet MJ | D3: Kč/MJ | E3: Kč celkem | G3: ='práce'!A1 -> Práce | H3: MJ | I3: počet MJ | J3: Kč/MJ | K3: Kč celkem | M3: ='služby'!A1 -> Služby | N3: MJ | O3: počet MJ | P3: Kč/MJ | Q3: Kč celkem
A4: ='materiál'!A3 -> Dřevo | B4: sada | C4: 1 | D4: ='materiál'!B12 -> 0 | E4: =C4*D4 -> 0 | G4: ='práce'!A67 -> Martin | H4: ='práce'!B4 -> hod | I4: ='práce'!C55 -> 0 | J4: ='práce'!D4 -> 500 | K4: ='práce'!E55 -> 0 | M4: ='služby'!A30 -> Doprava | N4: ks | O4: 1 | P4: ='služby'!B30 -> 0 | Q4: =O4*P4 -> 0
A5: ='materiál'!I3 -> Spojovací materiál | B5: sada | C5: 1 | D5: ='materiál'!B13 -> 50 | E5: =C5*D5 -> 50 | G5: ='práce'!A68 -> Vlaďka | H5: =H4 -> hod | I5: ='práce'!I55 -> 0 | J5: ='práce'!J4 -> 400 | K5: ='práce'!K55 -> 0 | M5: ='služby'!A31 -> Mechanizace | N5: ks | O5: 1 | P5: ='služby'!B31 -> 0 | Q5: =O5*P5 -> 0
A6: ='materiál'!Q3 -> Povrchovka | B6: sada | C6: 1 | D6: ='materiál'!B14 -> 0 | E6: =C6*D6 -> 0 | G6: ='práce'!A69 | H6: =H4 -> hod | I6: ='práce'!O55 -> 0 | J6: ='práce'!P4 -> 700 | K6: ='práce'!Q55 -> 0 | M6: ='služby'!A32 -> xxx | N6: ks | O6: 1 | P6: ='služby'!B32 -> 0 | Q6: =O6*P6 -> 0
A7: ='materiál'!A28 -> Brusný materiál | B7: sada | C7: 1 | D7: ='materiál'!B28 -> 0 | E7: =C7*D7 -> 0 | G7: ='práce'!A70 | H7: =H5 -> hod | I7: ='práce'!U55 -> 0 | J7: ='práce'!V4 -> 650 | K7: ='práce'!W55 -> 0 | M7: ='služby'!A33 -> xxx | N7: ks | O7: 1 | P7: ='služby'!B33 -> 0 | Q7: =O7*P7 -> 0
A8: ='materiál'!A29 -> xxx | B8: sada | C8: 1 | D8: ='materiál'!B29 -> 0 | E8: =C8*D8 -> 0 | G8: ='práce'!A71 | H8: =H6 -> hod | I8: ='práce'!AA55 -> 0 | J8: ='práce'!AB4 -> 650 | K8: ='práce'!AC55 -> 0 | M8: ='služby'!A34 -> xxx | N8: ks | O8: 1 | P8: ='služby'!B34 -> 0 | Q8: =O8*P8 -> 0
A9: ='materiál'!A30 -> xxx | B9: sada | C9: 1 | D9: ='materiál'!B30 -> 0 | E9: =C9*D9 -> 0 | G9: ='práce'!A72 | H9: =H7 -> hod | I9: ='práce'!AG55 -> 0 | J9: ='práce'!AH4 -> 700 | K9: ='práce'!AI55 -> 0 | M9: ='služby'!A35 -> xxx | N9: ks | O9: 1 | P9: ='služby'!B35 -> 0 | Q9: =O9*P9 -> 0
A10: ='materiál'!Y3 -> Materiál 12% DPH | B10: sada | C10: 1 | D10: ='materiál'!B15 -> 0 | E10: =C10*D10 -> 0 | G10: ='práce'!A73 | H10: =H9 -> hod | I10: ='práce'!AM55 -> 0 | J10: ='práce'!AN4 -> 600 | K10: ='práce'!AO55 -> 0 | M10: ='služby'!A36 -> xxx | N10: ks | O10: 1 | P10: ='služby'!B36 -> 0 | Q10: =O10*P10 -> 0
G11: ='práce'!A74 | H11: =H10 -> hod | I11: ='práce'!AS55 -> 0 | J11: ='práce'!AT4 -> 600 | K11: ='práce'!AU55 -> 0 | M11: ='služby'!A37 -> Ostatní | N11: ks | O11: 1 | P11: ='služby'!B37 -> 0 | Q11: =O11*P11 -> 0
G12: ='práce'!A75 | H12: =H8 -> hod | I12: ='práce'!AY55 -> 0 | J12: ='práce'!AZ4 -> 600 | K12: ='práce'!BA55 -> 0 | M12: ='služby'!A38 -> Sleva | N12: ks | O12: 1 | P12: ='služby'!B38 -> 0 | Q12: =O12*P12 -> 0
G13: ='práce'!A76 | H13: =H9 -> hod | I13: ='práce'!BE55 -> 0 | J13: ='práce'!BF4 -> 600 | K13: ='práce'!BG55 -> 0 | Q13: =O13*P13 -> 0
G14: ='práce'!BI3 | H14: =H13 -> hod | I14: ='práce'!BK55 -> 0 | J14: ='práce'!BL4 -> 800 | K14: ='práce'!BM55 -> 0 | Q14: =O14*P14 -> 0
G15: ='práce'!BO3 | H15: =H14 -> hod | I15: ='práce'!BQ55 -> 0 | J15: ='práce'!BR4 -> 650 | K15: ='práce'!BS55 -> 0
G16: ='práce'!BU3 | H16: =H15 -> hod | I16: ='práce'!BW55 -> 0 | J16: ='práce'!BX4 -> 950 | K16: ='práce'!BY55 -> 0
G17: ='práce'!CA3 | H17: =H16 -> hod | I17: ='práce'!CC55 -> 0 | J17: ='práce'!CD4 -> 600 | K17: ='práce'!CE55 -> 0
A18: Celkem | B18: x | C18: x | D18: x | E18: =SUM(E4:E14) -> 50 | G18: =A18 -> Celkem | H18: x | I18: =SUM(I4:I17) -> 0 | J18: x | K18: =SUM(K4:K17) -> 0 | M18: =A18 -> Celkem | N18: x | O18: x | P18: x | Q18: =SUM(Q4:Q14) -> 0
A20: =A3 -> Materiál | B20: =SUM(E4:E9) -> 50 | C20: =B25 -> 350 | D20: =B20/C20*100 -> 14.285714 | M20: =finance!A1 -> Finance | N20: MJ | O20: počet MJ | P20: Kč/MJ | Q20: Kč celkem
A21: Materiál 15% DPH | B21: =E10 -> 0 | C21: =C20 -> 350 | D21: =B21/C21*100 -> 0
A22: =G3 -> Práce | B22: =K18 -> 0 | C22: =C21 -> 350 | D22: =B22/C22*100 -> 0 | M22: =finance!A4 -> Kalkulace | N22: =finance!B4 -> hod | O22: =finance!C4 -> 0 | P22: =finance!D4 -> 600 | Q22: =O22*P22 -> 0
A23: =M3 -> Služby | B23: =SUM(Q4:Q11) -> 0 | C23: =C22 -> 350 | D23: =B23/C23*100 -> 0 | M23: =finance!A5 -> Fakturace | N23: =finance!B5 -> hod | O23: =finance!C5 -> 0.5 | P23: =finance!D5 -> 600 | Q23: =O23*P23 -> 300
A24: =M20 -> Finance | B24: =Q29 -> 300 | C24: =C23 -> 350 | D24: =B24/C24*100 -> 85.714286 | M24: =finance!A6 -> Návrh projektu | N24: =finance!B6 -> hod | O24: =finance!C6 -> 0 | P24: =finance!D6 -> 600 | Q24: =O24*P24 -> 0
A25: =A18 -> Celkem | B25: =SUM(B20:B24) -> 350 | C25: =C24 -> 350 | D25: =B25/C25*100 -> 100 | M25: =finance!A7 | N25: =finance!B7 | O25: =finance!C7 | P25: =finance!D7 | Q25: =O25*P25 -> 0
M26: =finance!A8 | N26: =finance!B8 | O26: =finance!C8 | P26: =finance!D8 | Q26: =O26*P26 -> 0
A27: Režijní náklady | M27: =finance!A9 | N27: =finance!B9 | O27: =finance!C9 | P27: =finance!D9 | Q27: =O27*P27 -> 0
M28: =finance!A10 | N28: =finance!B10 | O28: =finance!C10 | P28: =finance!D10 | Q28: =O28*P28 -> 0
A29: =A1 -> Jednicové náklady | D29: =SUM(B22:B24) -> 300 | E29: Kč | M29: =A18 -> Celkem | N29: x | O29: x | P29: x | Q29: =SUM(Q22:Q28) -> 300
A30: (Materiál 21% DPH) | D30: =B20 -> 50
A31: (materiál 15% DPH) | D31: =B21 -> 0 | E31: Kč
A33: =A27 -> Režijní náklady
A34: (Materiál 21% DPH) | B34: 47 | C34: % | D34: =D30*B34/100 -> 23.5 | E34: Kč
A35: (materiál 15% DPH) | B35: 47 | C35: % | D35: =D31*B35/100 -> 0 | E35: Kč
A37: Celkem: | D37: =SUM(D34:D35) -> 23.5
A39: Celkové náklady
A41: =A29 -> Jednicové náklady | D41: =SUM(D29:D31) -> 350 | E41: Kč
A42: =A33 -> Režijní náklady | D42: =D37 -> 23.5 | E42: Kč
A43: =A39 -> Celkové náklady | D43: =SUM(D41:D42) -> 373.5 | E43: Kč
A45: Zisk | O45: Fakturace se slevou:
S46: Ostatní materiál + mechanizace
A47: =A43 -> Celkové náklady | D47: =D43 -> 373.5 | E47: Kč | G47: Mezisoučet: | K47: Do Faktury: | O47: Do Faktury | Q47: Sleva: | S47: =(SUM(E5:E10)+Q5) -> 50 | T47: bez marže
...

Sheet výsledek
A1: ='součty'!A74 -> Cena s DPH | B1: ='součty'!D87 -> 509.41 | D1: ='zadání'!A3 -> Finanční limit: | E1: ='zadání'!C3 -> 0 | F1: % plnění | G1: =B1/E1*100 -> #DIV/0!
A3: Cena bez DPH | B3: ='součty'!D79 -> 421
A4: ='součty'!A29 -> Jednicové náklady
A5: ='materiál'!A1 -> Materiál | B5: ='součty'!E18 -> 50
A6: ='práce'!A1 -> Práce | B6: ='součty'!K18 -> 0
A7: ='služby'!A1 -> Služby | B7: ='součty'!Q18 -> 0
A8: =finance!A1 -> Finance | B8: ='součty'!Q29 -> 300
A9: ='součty'!A33 -> Režijní náklady | B9: ='součty'!D37 -> 23.5
A10: ='součty'!A45 -> Zisk | B10: ='součty'!D55 -> 47.5
A11: DPH | B11: ='součty'!D81+'součty'!D82 -> 88.41
